<?xml version="1.0"?>

<robot name="ARC_RCcar" xmlns:xacro="http://www.ros.org/wiki/xacro">

  <!-- Global namespace -->
  <xacro:arg name="robot_name" default="ARC_car" />
  <xacro:arg name="robot_skin" default="Blue" />

  <!-- ZED specs and its properties -->

    <xacro:arg name="camera_name"   default="zed" />
    <xacro:arg name="camera_model"  default="zed" />
    <xacro:arg name="base_frame"    default="zed_base_link" />
    <xacro:arg name="cam_pos_x"     default="0.0" />
    <xacro:arg name="cam_pos_y"     default="0.0" />
    <xacro:arg name="cam_pos_z"     default="0.0" />
    <xacro:arg name="cam_roll"      default="0.0" />
    <xacro:arg name="cam_pitch"     default="0.0" />
    <xacro:arg name="cam_yaw"       default="0.0" />

    <xacro:property name="M_PI"     value="3.1415926535897931" />
    <!--    <xacro:property name="zed_model"    value="$(arg camera_model)" />

    <xacro:if value="${zed_model == 'zed'}">
    -->
    <xacro:property name="baseline" value="0.12" />
  
    <!-- inertial parameter macros -->

 <xacro:macro name="chassis_inertial_params">
    <origin xyz="0.1477 0 0" rpy="0 0 0" />
    <mass value="4.0" />
    <inertia ixx="0.010609" ixy="0"          ixz="0"
                            iyy="0.050409"   iyz="0"
                                             izz="0.05865" />
  </xacro:macro>

  <xacro:macro name="left_wheels_inertial_params">
    <origin xyz="0 0 -0.0225" rpy="0 0 0" />
    <mass value="0.34055" />
    <inertia ixx="0.00026046" ixy="0"          ixz="0"
                              iyy="0.00026046" iyz="0"
                                               izz="0.00041226" />
  </xacro:macro>

  <xacro:macro name="right_wheels_inertial_params">
    <origin xyz="0 0 0.0225" rpy="0 0 0" />
    <mass value="0.34055" />
    <inertia ixx="0.00026046" ixy="0"          ixz="0"
                              iyy="0.00026046" iyz="0"
                                               izz="0.00041226" />
  </xacro:macro>

  <xacro:macro name="steering_hinge_inertial_params">
    <origin xyz="0 0 0" rpy="0 0 0" />
    <mass value="0.100" />
    <inertia ixx="4E-06" ixy="0"           ixz="0"
                              iyy="4E-06"  iyz="0"
                                                izz="4E-06" />
  </xacro:macro>

  <xacro:macro name="hokuyo_inertial_params">
    <origin xyz="0 0 0" rpy="0 0 0" />
    <mass value="0.130" />
    <inertia ixx="4E-06" ixy="0"           ixz="0"
                              iyy="4E-06"  iyz="0"
                                                izz="4E-06" />
  </xacro:macro>
<!-- Insert camera macros ZED ros wrapper --> 



<!-- geometry macros -->

  <xacro:macro name="chassis_geometry">
    <origin xyz="0.46 -0.135 -0.180" rpy="1.57 0 3.14" />
    <geometry>
      <mesh filename="package://rc_high/meshes/chassis.stl" scale="0.000990 0.0009375 0.0009375"/>
    </geometry>
  </xacro:macro>


  <xacro:macro name="left_rear_wheel_geometry">
    <origin xyz="0 0 0" rpy="0 0 0" />
    <geometry>
      <mesh filename="package://rc_high/meshes/left_wheel.stl" />
    </geometry>
  </xacro:macro>

  <xacro:macro name="right_rear_wheel_geometry">
    <origin xyz="0 0 0" rpy="0 0 0" />
    <geometry>
      <mesh filename="package://rc_high/meshes/right_wheel.stl" />
    </geometry>
  </xacro:macro>

  <xacro:macro name="left_front_wheel_geometry">
    <origin xyz="0 0 0" rpy="0 0 0" />
    <geometry>
      <mesh filename="package://rc_high/meshes/left_wheel.stl" />
    </geometry>
  </xacro:macro>

  <xacro:macro name="right_front_wheel_geometry">
    <origin xyz="0 0 0" rpy="0 0 0" />
    <geometry>
      <mesh filename="package://rc_high/meshes/right_wheel.stl" />
    </geometry>
  </xacro:macro>

  <xacro:macro name="left_steering_hinge_geometry">
    <origin xyz="0 0 0" rpy="0 0 0" />
    <geometry>
      <mesh filename="package://rc_high/meshes/hinge.stl" />
    </geometry>
  </xacro:macro>

  <xacro:macro name="right_steering_hinge_geometry">
    <origin xyz="0 0 0" rpy="0 0 0" />
    <geometry>
      <mesh filename="package://rc_high/meshes/hinge.stl" />
    </geometry>
  </xacro:macro>

  <xacro:macro name="left_wheels_collision_geometry">
    <origin xyz="0 0 -0.0225" rpy="0 0 0" />
    <geometry>
      <cylinder length="0.045" radius="0.05" />
    </geometry>
  </xacro:macro>

  <xacro:macro name="right_wheels_collision_geometry">
    <origin xyz="0 0 0.0225" rpy="0 0 0" />
    <geometry>e="robot_description"/>

      <cylinder length="0.045" radius="0.05" />
    </geometry>
  </xacro:macro>

  <!-- ADD chassis and its inertia link -->  
  
  <link name="$(arg robot_name)_base_link"/>

  <link name="$(arg robot_name)_chassis">
    <visual>
      <xacro:chassis_geometry/>
      <material name="red" />
    </visual>
  </link>

  <joint name="$(arg robot_name)_base_link_joint" type="fixed">
    <origin xyz="0 0 0.05" rpy="0 0 0" />
    <parent link="$(arg robot_name)_base_link" />
    <child link="$(arg robot_name)_chassis" />
  </joint>

  <link name="$(arg robot_name)_chassis_inertia">
    <inertial>
      <xacro:chassis_inertial_params />
    </inertial>
  </link>

  <joint name="$(arg robot_name)_chassis_inertia_joint" type="fixed">
    <origin xyz="0 0 0" rpy="0 0 0" />
    <parent link="$(arg robot_name)_chassis" />
    <child link="$(arg robot_name)_chassis_inertia" />
  </joint>

  <!-- Add the left rear wheel with its joints -->

  <link name="$(arg robot_name)_left_rear_wheel">
    <inertial>
      <xacro:left_wheels_inertial_params />
    </inertial>
    <visual>
      <xacro:left_rear_wheel_geometry />
      <material name="black" />
    </visual>
    <collision>robot
      <xacro:left_wheels_collision_geometry />
    </collision>
  </link>

  <joint name="$(arg robot_name)_left_rear_wheel_joint" type="continuous">
    <origin xyz="0 0.1 0" rpy="1.5708 0 0" />
    <parent link="$(arg robot_name)_chassis" />
    <child link="$(arg robot_name)_left_rear_wheel" />
    <axis xyz="0 0 -1" />
    <limit effort="10" velocity="100" />
  </joint>

    <!-- Add the right rear wheel with its joints -->

  <link name="$(arg robot_name)_right_rear_wheel">
    <inertial>
      <xacro:right_wheels_inertial_params />
    </inertial>
    <visual>
      <xacro:right_rear_wheel_geometry />
      <material name="black" />
    </visual>
    <collision>
      <xacro:right_wheels_collision_geometry />
    </collision>
  </link>

  <joint name="$(arg robot_name)_right_rear_wheel_joint" type="continuous">
    <origin xyz="0 -0.1 0" rpy="1.5708 0 0" />
    <parent link="$(arg robot_name)_chassis" />
    <child link="$(arg robot_name)_right_rear_wheel" />
    <axis xyz="0 0 -1" />
    <limit effort="10" velocity="100" />
  </joint>

 <!-- Add the steering hinge and its joints -->

 <link name="$(arg robot_name)_left_steering_hinge">
    <inertial>
      <xacro:steering_hinge_inertial_params />
    </inertial>
    <visual>
      <xacro:left_steering_hinge_geometry />
      <material name="grey" />
    </visual>
  </link>

  <joint name="$(arg robot_name)_left_steering_hinge_joint" type="revolute">
    <origin xyz="0.325 0.1 0" rpy="0 1.5708 0" />
    <parent link="$(arg robot_name)_chassis" />
    <child link="$(arg robot_name)_left_steering_hinge" />
    <axis xyz="-1 0 0" />
    <limit lower="-1.0" upper="1.0" effort="10" velocity="100" />
  </joint>

  <link name="$(arg robot_name)_right_steering_hinge">
    <inertial>
      <xacro:steering_hinge_inertial_params />
    </inertial>
    <visual>
      <xacro:right_steering_hinge_geometry />
      <material name="grey" />
    </visual>
  </link>

  <joint name="$(arg robot_name)_right_steering_hinge_joint" type="continuous">
    <origin xyz="0.325 -0.1 0" rpy="0 1.5708 0" />
    <parent link="$(arg robot_name)_chassis" />
    <child link="$(arg robot_name)_right_steering_hinge" />
    <axis xyz="-1 0 0" />
    <limit lower="-1.0" upper="1.0" effort="10" velocity="100" />
  </joint>

<!-- Add the left front wheel with its joints and tranmissions -->

  <link name="$(arg robot_name)_left_front_wheel">
    <inertial>
      <xacro:left_wheels_inertial_params />
    </inertial>
    <visual>
      <xacro:left_front_wheel_geometry />
      <material name="black" />
    </visual>
    <collision>
      <xacro:left_wheels_collision_geometry />
    </collision>
  </link>

  <joint name="$(arg robot_name)_left_front_wheel_joint" type="continuous">
    <origin xyz="0 0 0" rpy="1.5708 0 0" />
    <parent link="$(arg robot_name)_left_steering_hinge" />
    <child link="$(arg robot_name)_left_front_wheel" />
    <axis xyz="0 0 -1" />
    <limit effort="10" velocity="100" />
  </joint>


    <!-- Add the right front wheel with its joints and tranmissions -->

  <link name="$(arg robot_name)_right_front_wheel">
    <inertial>
      <xacro:right_wheels_inertial_params />
    </inertial>
    <visual>
      <xacro:right_front_wheel_geometry />
      <material name="black" />
    </visual>
    <collision>
      <xacro:right_wheels_collision_geometry />
    </collision>
  </link>

  <joint name="$(arg robot_name)_right_front_wheel_joint" type="continuous">
    <origin xyz="0 0 0" rpy="1.5708 0 0" />
    <parent link="$(arg robot_name)_right_steering_hinge" />
    <child link="$(arg robot_name)_right_front_wheel" />
    <axis xyz="0 0 -1" />
    <limit effort="10" velocity="100"/>
  </joint>

  <!-- Add Hokuyo laser scanner -->

  <link name="$(arg robot_name)_laser">
    <inertial>
      <xacro:hokuyo_inertial_params />
    </inertial>
    <collision>
      <origin xyz="0 0 0" rpy="0 0 0"/>
      <geometry>
        <box size="0.1 0.1 0.1"/>
      </geometry>
    </collision>
    <visual>
      <origin xyz="0 0 0" rpy="0 0 0"/>
      <geometry>
           <mesh filename="package://rc_high/meshes/hokuyo.stl"/>
        <material name="blue" />
      </geometry>
    </visual>
  </link>

  <joint name="$(arg robot_name)_hokuyo_joint" type="fixed">
	  <origin xyz="0.355 0.0 0.08" rpy="0 0 0"/>
          <parent link="$(arg robot_name)_chassis" />
          <child link="$(arg robot_name)_laser" />
          <axis xyz="0 0 1" />
  </joint>

  <!-- ADD ZED camera and its components -->
  
<!-- base_link -->
  <joint name="$(arg robot_name)_chassis_to_zed" type="fixed">
	  <origin xyz="0.400 0.0 0.065" rpy="0 0 0" />
	  <parent link="$(arg robot_name)_chassis" />
          <child link="$(arg base_frame)" />
	  <axis xyz="0 0 1" />
  </joint>

  
  <link name="$(arg base_frame)" />

  <!-- Camera Center -->
    <joint name="$(arg camera_name)_camera_center_joint" type="fixed">
        <parent link="$(arg base_frame)"/>
        <child link="$(arg camera_name)_camera_center"/>
        <origin xyz="$(arg cam_pos_x) $(arg cam_pos_y) $(arg cam_pos_z)" rpy="$(arg cam_roll) $(arg cam_pitch) $(arg cam_yaw)" />
    </joint>

    <link name="$(arg camera_name)_camera_center">
        <visual>
            <origin xyz="0 0 0" rpy="0 0 0"/>
            <geometry>
                <mesh filename="package://rc_high/meshes/zed.stl" />
            </geometry>
            <material name="zed_mat" />
        </visual>
    </link>
  
<!-- Left Camera -->
    <joint name="$(arg camera_name)_left_camera_joint" type="fixed">
        <parent link="$(arg camera_name)_camera_center"/>
        <child link="$(arg camera_name)_left_camera_frame"/>
        <origin xyz="0 ${baseline/2} 0" rpy="0 0 0" />
    </joint>

    <link name="$(arg camera_name)_left_camera_frame" />

    <joint name="$(arg camera_name)_left_camera_optical_joint" type="fixed">
        <origin xyz="0 0 0" rpy="-${M_PI/2} 0.0 -${M_PI/2}"/>
        <parent link="$(arg camera_name)_left_camera_frame"/>
        <child link="$(arg camera_name)_left_camera_optical_frame"/>
    </joint>

    <link name="$(arg camera_name)_left_camera_optical_frame"/>

<!-- Right Camera -->
    <joint name="$(arg camera_name)_right_camera_joint" type="fixed">
        <parent link="$(arg camera_name)_camera_center"/>
        <child link="$(arg camera_name)_right_camera_frame"/>
        <origin xyz="0 -${baseline/2} 0" rpy="0 0 0" />
    </joint>

    <link name="$(arg camera_name)_right_camera_frame" />

    <joint name="$(arg camera_name)_right_camera_optical_joint" type="fixed">
        <origin xyz="0 0 0" rpy="-${M_PI/2} 0.0 -${M_PI/2}"/>
        <parent link="$(arg camera_name)_right_camera_frame"/>
        <child link="$(arg camera_name)_right_camera_optical_frame"/>
    </joint>

    <link name="$(arg camera_name)_right_camera_optical_frame"/>


  <!--  ADD MATERIAL -->


  <material name="black">
    <color rgba="0.0 0.0 0.0 1.0"/>
  </material>

  <material name="blue">
    <color rgba="0.0 0.0 0.9 1.0"/>
  </material>

  <material name="green">
    <color rgba="0.0 0.8 0.0 1.0"/>
  </material>

  <material name="grey">
	  <color rgba="${191/255} ${191/255} ${191/255} 1.0"/>
  </material>

  <material name="orange">
    <color rgba="${255/255} ${108/255} ${10/255} 1.0"/>
  </material>

  <material name="brown">
    <color rgba="${222/255} ${207/255} ${195/255} 1.0"/>
  </material>

  <material name="red">
    <color rgba="0.8 0.0 0.0 1.0"/>
  </material>

  <material name="white">
    <color rgba="1.0 1.0 1.0 1.0"/>
  </material>

  <material name="zed_mat">
	  <color rgba="0.8 0.8 0.8 1.0" />
  </material>

</robot>

